Workbook

Sheet Summary
A1: [CLIENT NAME] — CHANNEL STRATEGY SUMMARY
A2: Green values = linked from detail tabs. Yellow cells = adjustable inputs.
A4: CHANNEL ROLES
A5: [Primary Channel 1] | B5: [Role Title]
A6: [Role description — 1-2 sentences]
A7: [Primary Channel 2] | B7: [Role Title]
A8: [Role description — 1-2 sentences]
A9: [Supporting Channel] | B9: [Role Title]
A10: [Role description — 1-2 sentences]
A12: INVESTMENT OVERVIEW
A13: Channel | B13: Monthly Retainer | C13: Monthly Ad Spend | D13: Total Monthly | E13: Notes
A14: [Channel 1] | B14: [retainer] | C14: [ad spend] | D14: [total] | E14: [notes]
A15: [Channel 2] | B15: [retainer] | C15: [ad spend] | D15: [total] | E15: [notes]
A16: [Channel 3] | B16: [retainer] | C16: [ad spend] | D16: [total] | E16: [notes]
A17: TOTAL | B17: =SUM(B14:B16) | C17: =SUM(C14:C16) | D17: =SUM(D14:D16)
A19: GOOGLE ADS PROJECTED PERFORMANCE | C19: DATA-BACKED ESTIMATE
A20: Metric | B20: [Service Line 1] | C20: [Service Line 2]
A21: Monthly Ad Budget | B21: ='Google Ads'!B9 | C21: ='Google Ads'!C9
A22: Avg CPC | B22: ='Google Ads'!B8 | C22: ='Google Ads'!C8
A23: Monthly Clicks | B23: ='Google Ads'!B20 | C23: ='Google Ads'!C20
A24: LP Conversion Rate | B24: ='Google Ads'!B10 | C24: ='Google Ads'!C10
A25: Monthly Leads | B25: ='Google Ads'!B21 | C25: ='Google Ads'!C21
A26: Sales Closing Rate | B26: ='Google Ads'!B11 | C26: ='Google Ads'!C11
A27: New Clients/Month | B27: ='Google Ads'!B23 | C27: ='Google Ads'!C23
A28: Monthly Revenue | B28: ='Google Ads'!B27 | C28: ='Google Ads'!C27
A29: Ad Spend ROAS | B29: ='Google Ads'!B28 | C29: ='Google Ads'!C28
A30: Cost Per Acquisition | B30: ='Google Ads'!B24 | C30: ='Google Ads'!C24
A32: META ADS PROJECTED PERFORMANCE | C32: MODELED ESTIMATE
A33: Metric | B33: [Service Line 1] | C33: [Service Line 2]
A34: Monthly Ad Budget | B34: ='Meta Ads'!B9 | C34: ='Meta Ads'!C9
A35: CPM | B35: ='Meta Ads'!B10 | C35: ='Meta Ads'!C10
A36: Effective CPC | B36: ='Meta Ads'!B12 | C36: ='Meta Ads'!C12
A37: Monthly Leads | B37: ='Meta Ads'!B27 | C37: ='Meta Ads'!C27
A38: New Clients/Month | B38: ='Meta Ads'!B29 | C38: ='Meta Ads'!C29
A39: Monthly Revenue | B39: ='Meta Ads'!B31 | C39: ='Meta Ads'!C31
A40: Ad Spend ROAS | B40: ='Meta Ads'!B32 | C40: ='Meta Ads'!C32
A41: Cost Per Acquisition | B41: ='Meta Ads'!B30 | C41: ='Meta Ads'!C30
A43: KEY TAKEAWAYS
A44: 1. [Takeaway 1: Primary channel role and foundation]
A45: 2. [Takeaway 2: Secondary channel complement]
...

Sheet Google Ads
A1: [CLIENT NAME] — GOOGLE ADS PROJECTIONS
A2: DATA-BACKED ESTIMATE — Built from real keyword data (Step 3 Market Research)
A3: Yellow = adjustable inputs (blue text). Green = auto-calculated.
A5: Metric | B5: [Service Line 1] | C5: [Service Line 2] | D5: Notes
A6: DFY Management Retainer | B6: 0 | D6: Fixed monthly management fee
A8: Avg CPC | B8: 0 | C8: 0 | D8: From Step 3 keyword data
A9: Monthly Ad Budget | B9: 0 | C9: 0 | D9: Adjustable input
A10: LP Conversion Rate | B10: 0 | C10: 0 | D10: Landing page visitor → lead
A11: Sales Closing Rate | B11: 0 | C11: 0 | D11: Lead → paying client
A13: REVENUE PER CLIENT
A14: [Service Line 1] Price | B14: 0 | D14: From Step 5 Offer Dev
A15: [Service Line 2] Rate | C15: 0 | D15: Hourly/per-unit rate
A16: Est. Units/Engagement | C16: 0 | D16: Hours, sessions, units per engagement
A17: Revenue Per Client | B17: =B14 | C17: =C15*C16 | D17: Line 1 = flat price; Line 2 = rate × units
A19: PROJECTED PERFORMANCE
A20: Monthly Clicks | B20: =IF(B8>0,B9/B8,0) | C20: =IF(C8>0,C9/C8,0) | D20: =Budget ÷ CPC
A21: Monthly Leads | B21: =B20*B10 | C21: =C20*C10 | D21: =Clicks × Conv Rate
A22: Cost Per Lead | B22: =IF(B21>0,B9/B21,0) | C22: =IF(C21>0,C9/C21,0) | D22: =Budget ÷ Leads
A23: New Clients/Month | B23: =B21*B11 | C23: =C21*C11 | D23: =Leads × Close Rate
A24: Cost Per Acquisition | B24: =IF(B23>0,B9/B23,0) | C24: =IF(C23>0,C9/C23,0) | D24: =Ad Spend ÷ Clients
A26: REVENUE & PROFITABILITY
A27: Monthly Revenue | B27: =B23*B17 | C27: =C23*C17 | D27: =Clients × Rev/Client
A28: Ad Spend ROAS | B28: =IF(B9>0,B27/B9,0) | C28: =IF(C9>0,C27/C9,0) | D28: =Revenue ÷ Ad Spend only
A29: Monthly Profit (ad spend only) | B29: =B27-B9 | C29: =C27-C9 | D29: =Revenue − Ad Spend
A30: Profit Margin (ad spend only) | B30: =IF(B27>0,B29/B27,0) | C30: =IF(C27>0,C29/C27,0)
A33: COMBINED CHANNEL PROFITABILITY
A34: Metric | D34: Combined
A35: Total Ad Spend | D35: =B9+C9
A36: Management Retainer | D36: =B6
A37: Total Investment | D37: =D35+D36
A38: Total Revenue | D38: =B27+C27
A39: Total New Clients | D39: =B23+C23
A40: CPA (total investment) | D40: =IF(D39>0,D37/D39,0)
A41: True ROAS (incl. retainer) | D41: =IF(D37>0,D38/D37,0)
A42: Profit (after all costs) | D42: =D38-D37
A43: Profit Margin | D43: =IF(D38>0,D42/D38,0)

Sheet Meta Ads
A1: [CLIENT NAME] — META ADS PROJECTIONS
A2: MODELED ESTIMATE — Built from industry CPM/CTR benchmarks
A3: Yellow = adjustable inputs (blue text). Green = auto-calculated.
A5: Metric | B5: [Service Line 1] | C5: [Service Line 2] | D5: Notes
A6: DFY Management Retainer | B6: 0 | D6: Fixed monthly management fee
A8: Daily Ad Budget | B8: 0 | C8: 0 | D8: Per-day ad spend
A9: Monthly Ad Budget | B9: =B8*30 | C9: =C8*30 | D9: =Daily × 30
A10: CPM | B10: 0 | C10: 0 | D10: Cost per 1,000 impressions (benchmark)
A11: CTR | B11: 0 | C11: 0 | D11: Click-through rate (benchmark)
A12: Effective CPC | B12: =IF(B11>0,B10/(B11*1000),0) | C12: =IF(C11>0,C10/(C11*1000),0) | D12: =CPM ÷ (CTR × 1000)
A14: CONVERSION INPUTS
A15: LP Conversion Rate | B15: 0 | C15: 0 | D15: Landing page visitor → lead
A16: Sales Closing Rate | B16: 0 | C16: 0 | D16: Lead → paying client
A18: REVENUE
A19: Revenue Per Client | B19: 0 | C19: 0 | D19: From Step 5 Offer Dev
A21: PROJECTED PERFORMANCE
A22: Monthly Impressions | B22: =IF(B10>0,B9/B10*1000,0) | C22: =IF(C10>0,C9/C10*1000,0) | D22: =Budget ÷ CPM × 1000
A23: Monthly Clicks | B23: =B22*B11 | C23: =C22*C11 | D23: =Impressions × CTR
A24: Cost Per Click | B24: =IF(B23>0,B9/B23,0) | C24: =IF(C23>0,C9/C23,0)
A26: CONVERSION FUNNEL
A27: Monthly Leads | B27: =B23*B15 | C27: =C23*C15 | D27: =Clicks × LP Conv Rate
A28: Cost Per Lead | B28: =IF(B27>0,B9/B27,0) | C28: =IF(C27>0,C9/C27,0)
A29: New Clients/Month | B29: =B27*B16 | C29: =C27*C16 | D29: =Leads × Close Rate
A30: Cost Per Acquisition | B30: =IF(B29>0,B9/B29,0) | C30: =IF(C29>0,C9/C29,0) | D30: =Ad Spend ÷ Clients
A31: Monthly Revenue | B31: =B29*B19 | C31: =C29*C19 | D31: =Clients × Rev/Client
A32: Ad Spend ROAS | B32: =IF(B9>0,B31/B9,0) | C32: =IF(C9>0,C31/C9,0) | D32: =Revenue ÷ Ad Spend only
A33: Monthly Profit (ad spend only) | B33: =B31-B9 | C33: =C31-C9
A34: Profit Margin (ad spend only) | B34: =IF(B31>0,B33/B31,0) | C34: =IF(C31>0,C33/C31,0)
A37: COMBINED CHANNEL PROFITABILITY
A38: Metric | D38: Combined
A39: Total Ad Spend | D39: =B9+C9
A40: Management Retainer | D40: =B6
A41: Total Investment | D41: =D39+D40
A42: Total Revenue | D42: =B31+C31
A43: Total New Clients | D43: =B29+C29
A44: CPA (total investment) | D44: =IF(D43>0,D41/D43,0)
A45: True ROAS (incl. retainer) | D45: =IF(D41>0,D42/D41,0)
A46: Profit (after all costs) | D46: =D42-D41
A47: Profit Margin | D47: =IF(D42>0,D46/D42,0)
A49: BENCHMARK SOURCES
...

Sheet Content & SEO
A1: [CLIENT NAME] — CONTENT & SEO FOUNDATION
A2: Page inventory and SEO services to support channel strategy.
A4: CONTENT MARKETING
A5: Deliverable | B5: Pages | C5: Cost/Page | D5: Subtotal | E5: Notes
A6: [Page Category 1] | B6: 0 | C6: 0 | D6: =B6*C6 | E6: [description]
A7: [Page Category 2] | B7: 0 | C7: 0 | D7: =B7*C7 | E7: [description]
A8: [Page Category 3] | B8: 0 | C8: 0 | D8: =B8*C8 | E8: [description]
A9: [Page Category 4] | B9: 0 | C9: 0 | D9: =B9*C9 | E9: [description]
A10: [Page Category 5] | B10: 0 | C10: 0 | D10: =B10*C10 | E10: [description]
A11: [Page Category 6] | B11: 0 | C11: 0 | D11: =B11*C11 | E11: [description]
A12: Content Marketing Subtotal | B12: =SUM(B6:B11) | D12: =SUM(D6:D11)
A14: SEO SERVICES
A15: Service | B15: Details | C15: Monthly Cost
A16: [Service 1] | B16: [description] | C16: 0
A17: [Service 2] | B17: [description] | C17: 0
A18: [Service 3] | B18: [description] | C18: 0
A20: ONE-TIME COSTS
A21: [One-time service] | C21: 0 | D21: [description]
A23: INVESTMENT SUMMARY
A24: Content Marketing (one-time) | C24: =D12
A25: One-time Costs | C25: =C21
A26: Total One-Time Investment | C26: =C24+C25
A28: Monthly SEO Services | C28: =SUM(C16:C18) | D28: Ongoing monthly cost
